

<robot name="nashbot">
<link name="link_lead_screw">
<visual>
<origin xyz="-0.028031642234836610938 -0.13539226875249418813 0.080270123761849734856" rpy="-1.3877791116502955134e-17 -4.5818937591147125869e-16 1.5707963267948921171" />
<geometry>
<mesh filename="package://nashbot/description/link_lead_screw.stl"/>
</geometry>
<material name="link_lead_screw_material">
<color rgba="0.61568627450980395466 0.81176470588235294379 0.92941176470588238168 1.0"/>
</material>
</visual>
<collision>
<origin xyz="-0.028031642234836610938 -0.13539226875249418813 0.080270123761849734856" rpy="-1.3877791116502955134e-17 -4.5818937591147125869e-16 1.5707963267948921171" />
<geometry>
<mesh filename="package://nashbot/description/link_lead_screw.stl"/>
</geometry>
</collision>
<inertial>
<origin xyz="-0.028031642234836607469 -0.13539226875249418813 0.093449700991282219631" rpy="0 0 0"/>
<mass value="0.044274795134269594177" />
<inertia ixx="5.9007712889422220178e-06" ixy="2.6406508355513240935e-20"  ixz="1.0916475297711825399e-21" iyy="5.9007712889422643694e-06" iyz="2.383841110744119013e-21" izz="3.8410252887780899555e-06" />
</inertial>
</link>

<link name="link_arm_mount_base">
<visual>
<origin xyz="0.10500000000000002387 -0.18000000000000002109 -0.009999999999999995004" rpy="0 -1.5407439555097886824e-33 1.155557966632338946e-33" />
<geometry>
<mesh filename="package://nashbot/description/link_arm_mount_base.stl"/>
</geometry>
<material name="link_arm_mount_base_material">
<color rgba="0 0 0 1.0"/>
</material>
</visual>
<collision>
<origin xyz="0.10500000000000002387 -0.18000000000000002109 -0.009999999999999995004" rpy="0 -1.5407439555097886824e-33 1.155557966632338946e-33" />
<geometry>
<mesh filename="package://nashbot/description/link_arm_mount_base.stl"/>
</geometry>
</collision>
<inertial>
<origin xyz="0.035003417238566120195 -0.080546758170579269009 -0.0049999999999999948999" rpy="0 0 0"/>
<mass value="0.3476241705557227557" />
<inertia ixx="0.0011542363387682392627" ixy="-9.5682679851351873104e-08"  ixz="1.7783826621869134124e-36" iyy="0.00057171713853165859881" iyz="-1.4742251062794864436e-40" izz="0.0017201597411239690199" />
</inertial>
</link>

<link name="link_lead_screw_2">
<visual>
<origin xyz="0 0 -0.0019999999999999878986" rpy="0 -1.232595164407830946e-32 -1.1555579666312777087e-33" />
<geometry>
<mesh filename="package://nashbot/description/link_lead_screw.stl"/>
</geometry>
<material name="link_lead_screw_material">
<color rgba="0.61568627450980395466 0.81176470588235294379 0.92941176470588238168 1.0"/>
</material>
</visual>
<collision>
<origin xyz="0 0 -0.0019999999999999878986" rpy="0 -1.232595164407830946e-32 -1.1555579666312777087e-33" />
<geometry>
<mesh filename="package://nashbot/description/link_lead_screw.stl"/>
</geometry>
</collision>
<inertial>
<origin xyz="-3.3480423142111705257e-19 8.409802983138248567e-19 0.011179577229432420549" rpy="0 0 0"/>
<mass value="0.044274795134269594177" />
<inertia ixx="5.9007712889420881866e-06" ixy="2.1463470860522140012e-36"  ixz="7.2732621570265817115e-38" iyy="5.9007712889420881866e-06" iyz="-8.4046760289498575363e-71" izz="3.8410252887780425217e-06" />
</inertial>
</link>

<joint name="slider_bearing2" type="fixed">
<origin xyz="0.068999999999999991895 -2.7755575615628913511e-17 -1.3877787807814456755e-17" rpy="3.4773505634435970465e-16 3.8210450096641918546e-31 1.570796326794896558" />
<parent link="link_arm_mount_base" />
<child link="link_lead_screw_2" />
<axis xyz="0 0 1"/>
<limit effort="1" velocity="20" />
<joint_properties friction="0.0"/>
</joint>

<link name="link_arm1">
<visual>
<origin xyz="0 4.336808689942017736e-18 0" rpy="3.141592653589793116 -0 -3.8518598887850806576e-34" />
<geometry>
<mesh filename="package://nashbot/description/link_arm1.stl"/>
</geometry>
<material name="link_arm1_material">
<color rgba="0.37254901960784314596 0.65490196078431373028 0.23921568627450981448 1.0"/>
</material>
</visual>
<collision>
<origin xyz="0 4.336808689942017736e-18 0" rpy="3.141592653589793116 -0 -3.8518598887850806576e-34" />
<geometry>
<mesh filename="package://nashbot/description/link_arm1.stl"/>
</geometry>
</collision>
<inertial>
<origin xyz="-1.8370485490845299587e-18 -1.9807713140317773363e-18 -0.012500000000000016306" rpy="0 0 0"/>
<mass value="0.065384397102838151539" />
<inertia ixx="0.0001525524414595170531" ixy="-3.1957421044861665813e-36"  ixz="0" iyy="0.00015255244145951702599" iyz="0" izz="0.0002982940082208218103" />
</inertial>
</link>

<link name="link_arm1_base">
<visual>
<origin xyz="-0.24892457063198081268 -4.336808689942017736e-18 -0.014999999999999999445" rpy="0 -0 1.1555579666297065507e-33" />
<geometry>
<mesh filename="package://nashbot/description/link_arm1_base.stl"/>
</geometry>
<material name="link_arm1_base_material">
<color rgba="0 0 0 1.0"/>
</material>
</visual>
<collision>
<origin xyz="-0.24892457063198081268 -4.336808689942017736e-18 -0.014999999999999999445" rpy="0 -0 1.1555579666297065507e-33" />
<geometry>
<mesh filename="package://nashbot/description/link_arm1_base.stl"/>
</geometry>
</collision>
<inertial>
<origin xyz="-0.067724570631980812729 2.0005385637791788029e-18 -0.0075000000000000066613" rpy="0 0 0"/>
<mass value="0.039230638261702789615" />
<inertia ixx="9.0223776933653459771e-05" ixy="1.5004659150170553936e-35"  ixz="0" iyy="9.0223776933653419114e-05" iyz="0" izz="0.00017897640493249301571" />
</inertial>
</link>

<link name="link_arm1_bearing">
<visual>
<origin xyz="-0.46200000000000002176 0 -0.024999999999999994449" rpy="0 -0 -5.5511151231258924031e-17" />
<geometry>
<mesh filename="package://nashbot/description/link_arm1_bearing.stl"/>
</geometry>
<material name="link_arm1_bearing_material">
<color rgba="0.2313725490196078538 0.38039215686274507888 0.7058823529411765163 1.0"/>
</material>
</visual>
<collision>
<origin xyz="-0.46200000000000002176 0 -0.024999999999999994449" rpy="0 -0 -5.5511151231258924031e-17" />
<geometry>
<mesh filename="package://nashbot/description/link_arm1_bearing.stl"/>
</geometry>
</collision>
<inertial>
<origin xyz="-5.5511151231257827021e-17 -1.9768463689639289003e-17 -0.012500000000000009368" rpy="0 0 0"/>
<mass value="0.060475658581603579378" />
<inertia ixx="0.00012144759880165811091" ixy="-6.7416960237522373133e-21"  ixz="0" iyy="0.00012144759880165801604" iyz="4.666026462492941371e-35" izz="0.00023659564983439916206" />
</inertial>
</link>

<link name="link_arm1_top_mount">
<visual>
<origin xyz="-2.3828835793437974644e-08 -7.7936529123828757193e-06 -0.015000000000000013323" rpy="0 -0 1.0680181539507714832e-30" />
<geometry>
<mesh filename="package://nashbot/description/link_arm1_top_mount.stl"/>
</geometry>
<material name="link_arm1_top_mount_material">
<color rgba="0.91764705882352937127 0.91764705882352937127 0.91764705882352937127 1.0"/>
</material>
</visual>
<collision>
<origin xyz="-2.3828835793437974644e-08 -7.7936529123828757193e-06 -0.015000000000000013323" rpy="0 -0 1.0680181539507714832e-30" />
<geometry>
<mesh filename="package://nashbot/description/link_arm1_top_mount.stl"/>
</geometry>
</collision>
<inertial>
<origin xyz="1.4378696666169252801e-10 4.7028134971059242647e-08 -0.0075000000000000136002" rpy="0 0 0"/>
<mass value="0.24404755337625547162" />
<inertia ixx="0.0002655499667277153638" ixy="2.7510661027997182977e-16"  ixz="0" iyy="0.00026554996681770273465" iyz="0" izz="0.00052194815029380859164" />
</inertial>
</link>

<link name="link_arm2">
<visual>
<origin xyz="0.16170000000000001039 0 0" rpy="3.141592653589793116 1.9721522630525290756e-31 9.5219797823659113582e-31" />
<geometry>
<mesh filename="package://nashbot/description/link_arm2.stl"/>
</geometry>
<material name="link_arm2_material">
<color rgba="0.19607843137254901689 0.43921568627450979783 0.078431372549019606755 1.0"/>
</material>
</visual>
<collision>
<origin xyz="0.16170000000000001039 0 0" rpy="3.141592653589793116 1.9721522630525290756e-31 9.5219797823659113582e-31" />
<geometry>
<mesh filename="package://nashbot/description/link_arm2.stl"/>
</geometry>
</collision>
<inertial>
<origin xyz="-0.0070071560830908263817 -6.581965755528475191e-19 -0.032046723511373838289" rpy="0 0 0"/>
<mass value="0.2521046695326249476" />
<inertia ixx="0.00058788852463160829083" ixy="4.4933226750299111104e-20"  ixz="-4.4024229691094070272e-05" iyy="0.00040472252649839359417" iyz="-4.1919782505283081074e-35" izz="0.00067793839878907337804" />
</inertial>
</link>

<link name="link_arm3">
<visual>
<origin xyz="0.25509999999999999343 0.32916826553344719075 -0.033300000000000093414" rpy="1.570796326794896558 -8.2428688193495407456e-18 -5.5511151231257839347e-17" />
<geometry>
<mesh filename="package://nashbot/description/link_arm3.stl"/>
</geometry>
<material name="link_arm3_material">
<color rgba="0 0.35686274509803922461 0.32941176470588234837 1.0"/>
</material>
</visual>
<collision>
<origin xyz="0.25509999999999999343 0.32916826553344719075 -0.033300000000000093414" rpy="1.570796326794896558 -8.2428688193495407456e-18 -5.5511151231257839347e-17" />
<geometry>
<mesh filename="package://nashbot/description/link_arm3.stl"/>
</geometry>
</collision>
<inertial>
<origin xyz="2.2204460492503130808e-16 0.064550407698123923872 -0.025000000000000070777" rpy="0 0 0"/>
<mass value="0.12431354679013277564" />
<inertia ixx="0.00031684724085741288249" ixy="-2.5687314900064670096e-20"  ixz="-1.5775851533978057483e-20" iyy="7.2947143195453193983e-05" iyz="1.3063275367503041351e-20" izz="0.00029894005134427559982" />
</inertial>
</link>

<link name="link_arm4">
<visual>
<origin xyz="0.20099999999999998423 -0.23399999999999993028 -0.24900000000000005462" rpy="-1.570796326794896558 7.1347324311582933715e-18 -5.5511151231257827021e-17" />
<geometry>
<mesh filename="package://nashbot/description/link_arm4.stl"/>
</geometry>
<material name="link_arm4_material">
<color rgba="0.14117647058823529216 0.6941176470588235059 0.65098039215686276382 1.0"/>
</material>
</visual>
<collision>
<origin xyz="0.20099999999999998423 -0.23399999999999993028 -0.24900000000000005462" rpy="-1.570796326794896558 7.1347324311582933715e-18 -5.5511151231257827021e-17" />
<geometry>
<mesh filename="package://nashbot/description/link_arm4.stl"/>
</geometry>
</collision>
<inertial>
<origin xyz="0 -0.084999999999999936717 -0.015000000000000056691" rpy="0 0 0"/>
<mass value="0.12168204910675753383" />
<inertia ixx="0.00041405059351792020345" ixy="-2.2984425114165330153e-20"  ixz="2.0837050571829986369e-20" iyy="2.65985492948486828e-05" iyz="1.0180550114122810527e-20" izz="0.00041438478586950451728" />
</inertial>
</link>

<link name="link_wrist_mid">
<visual>
<origin xyz="-0.058799999999999963407 0.012500000000000011102 0.016000000000000014211" rpy="1.570796326794896558 1.570796326794896336 0" />
<geometry>
<mesh filename="package://nashbot/description/link_wrist_mid.stl"/>
</geometry>
<material name="link_wrist_mid_material">
<color rgba="0.61568627450980395466 0.81176470588235294379 0.92941176470588238168 1.0"/>
</material>
</visual>
<collision>
<origin xyz="-0.058799999999999963407 0.012500000000000011102 0.016000000000000014211" rpy="1.570796326794896558 1.570796326794896336 0" />
<geometry>
<mesh filename="package://nashbot/description/link_wrist_mid.stl"/>
</geometry>
</collision>
<inertial>
<origin xyz="3.5104411915449336318e-17 0.0051151343140878819185 0.01600000000000002115" rpy="0 0 0"/>
<mass value="0.025315413537536850253" />
<inertia ixx="7.864055029639285455e-06" ixy="-8.4654521520664855803e-23"  ixz="-1.327938248542003278e-21" iyy="9.3890553159420558888e-06" iyz="2.4153227458552780771e-21" izz="8.0187605486312163921e-06" />
</inertial>
</link>

<link name="link_wrist_base_bearing">
<visual>
<origin xyz="-5.5511151231257827021e-17 -2.7755575615628913511e-17 0.005000000000000059952" rpy="3.141592653589793116 5.5511151231257839347e-17 -5.5511151231257839347e-17" />
<geometry>
<mesh filename="package://nashbot/description/link_wrist_base_bearing.stl"/>
</geometry>
<material name="link_wrist_base_bearing_material">
<color rgba="0.64705882352941179736 0.64705882352941179736 0.64705882352941179736 1.0"/>
</material>
</visual>
<collision>
<origin xyz="-5.5511151231257827021e-17 -2.7755575615628913511e-17 0.005000000000000059952" rpy="3.141592653589793116 5.5511151231257839347e-17 -5.5511151231257839347e-17" />
<geometry>
<mesh filename="package://nashbot/description/link_wrist_base_bearing.stl"/>
</geometry>
</collision>
<inertial>
<origin xyz="-5.3449969326784905421e-17 -2.8707687169804345526e-17 5.9847959921199844757e-17" rpy="0 0 0"/>
<mass value="0.0023389497908041681322" />
<inertia ixx="3.3473362730383543815e-07" ixy="-1.8581449007450703167e-23"  ixz="-5.3580383763024627922e-23" iyy="3.3473362730383517345e-07" iyz="-6.9997869511147837754e-23" izz="6.3048475809426801023e-07" />
</inertial>
</link>

<link name="link_wrist_base">
<visual>
<origin xyz="2.2204460492503130808e-16 0 -0.025000000000000077716" rpy="5.5511151231257827021e-17 -2.7755575615628919674e-17 -5.5511151231257839347e-17" />
<geometry>
<mesh filename="package://nashbot/description/link_wrist_base.stl"/>
</geometry>
<material name="link_wrist_base_material">
<color rgba="0.2313725490196078538 0.38039215686274507888 0.7058823529411765163 1.0"/>
</material>
</visual>
<collision>
<origin xyz="2.2204460492503130808e-16 0 -0.025000000000000077716" rpy="5.5511151231257827021e-17 -2.7755575615628919674e-17 -5.5511151231257839347e-17" />
<geometry>
<mesh filename="package://nashbot/description/link_wrist_base.stl"/>
</geometry>
</collision>
<inertial>
<origin xyz="2.2064750165214164416e-16 1.6743681029369050529e-18 -0.011821527754878845273" rpy="0 0 0"/>
<mass value="0.012997117333615264625" />
<inertia ixx="2.7433540531637970571e-06" ixy="-4.5686022517817920135e-22"  ixz="-5.4316774396845677412e-22" iyy="2.7433540531637983276e-06" iyz="1.5228674172605973378e-22" izz="4.4626068895703836816e-06" />
</inertial>
</link>

<link name="link_wrist_end">
<visual>
<origin xyz="-5.5511151231257827021e-17 -0.058799999999999963407 -0.062700000000000033484" rpy="-2.7755575615628913511e-17 -0 0" />
<geometry>
<mesh filename="package://nashbot/description/link_wrist_end.stl"/>
</geometry>
<material name="link_wrist_end_material">
<color rgba="0.08627450980392156743 0.32156862745098041545 0.5803921568627451455 1.0"/>
</material>
</visual>
<collision>
<origin xyz="-5.5511151231257827021e-17 -0.058799999999999963407 -0.062700000000000033484" rpy="-2.7755575615628913511e-17 -0 0" />
<geometry>
<mesh filename="package://nashbot/description/link_wrist_end.stl"/>
</geometry>
</collision>
<inertial>
<origin xyz="-7.0247061093412127652e-17 2.93454979590583218e-18 0.026232074734683308304" rpy="0 0 0"/>
<mass value="0.017319283609535641999" />
<inertia ixx="4.8738112711665619847e-06" ixy="2.7507330739909891865e-12"  ixz="-7.6348179833568263388e-29" iyy="6.3813706712216062902e-06" iyz="5.267352462003737323e-22" izz="6.339751984827221004e-06" />
</inertial>
</link>

<link name="link_arm_wrist2">
<visual>
<origin xyz="-0.0081956442445518251638 -0.0075000000000000621725 5.5511151231257827021e-17" rpy="-1.57079632679489678 -1.570796326794896336 0" />
<geometry>
<mesh filename="package://nashbot/description/link_arm_wrist2.stl"/>
</geometry>
<material name="link_arm_wrist2_material">
<color rgba="0 0 0 1.0"/>
</material>
</visual>
<collision>
<origin xyz="-0.0081956442445518251638 -0.0075000000000000621725 5.5511151231257827021e-17" rpy="-1.57079632679489678 -1.570796326794896336 0" />
<geometry>
<mesh filename="package://nashbot/description/link_arm_wrist2.stl"/>
</geometry>
</collision>
<inertial>
<origin xyz="0.01687189633981396597 -6.6786853825107073135e-17 -0.013174576908349939011" rpy="0 0 0"/>
<mass value="0.0076395059073011530384" />
<inertia ixx="9.9049260207194373556e-07" ixy="-3.0630797409723637865e-22"  ixz="-3.3598045264685168607e-22" iyy="3.0417224068398414207e-06" iyz="-4.5896522826507133167e-23" izz="2.3476594558161568772e-06" />
</inertial>
</link>

<link name="link_armlast">
<visual>
<origin xyz="-5.5511151231257827021e-17 -5.5511151231257827021e-17 0.010000000000000064393" rpy="-3.141592653589793116 1.1102230246251565404e-16 -2.7755575615628913511e-17" />
<geometry>
<mesh filename="package://nashbot/description/link_armlast.stl"/>
</geometry>
<material name="link_armlast_material">
<color rgba="0 0 0 1.0"/>
</material>
</visual>
<collision>
<origin xyz="-5.5511151231257827021e-17 -5.5511151231257827021e-17 0.010000000000000064393" rpy="-3.141592653589793116 1.1102230246251565404e-16 -2.7755575615628913511e-17" />
<geometry>
<mesh filename="package://nashbot/description/link_armlast.stl"/>
</geometry>
</collision>
<inertial>
<origin xyz="-5.6119821502383543601e-17 -5.6591051786074563839e-17 0.0050000000000000642889" rpy="0 0 0"/>
<mass value="0.023029890215175794627" />
<inertia ixx="3.9323633187538940061e-06" ixy="-1.0914500744179916908e-22"  ixz="-4.3658002976719667633e-22" iyy="3.9323633187538948531e-06" iyz="-6.668286910858981915e-22" izz="7.4808951339215242534e-06" />
</inertial>
</link>

<link name="link_armlast2">
<visual>
<origin xyz="5.5511151231257827021e-17 -0.024600000000000066258 -0.010000000000000008882" rpy="4.1633363423443376429e-17 -0 -2.7755575615628913511e-17" />
<geometry>
<mesh filename="package://nashbot/description/link_armlast2.stl"/>
</geometry>
<material name="link_armlast2_material">
<color rgba="0 0 0 1.0"/>
</material>
</visual>
<collision>
<origin xyz="5.5511151231257827021e-17 -0.024600000000000066258 -0.010000000000000008882" rpy="4.1633363423443376429e-17 -0 -2.7755575615628913511e-17" />
<geometry>
<mesh filename="package://nashbot/description/link_armlast2.stl"/>
</geometry>
</collision>
<inertial>
<origin xyz="5.2725570047167508158e-17 -7.292777493006496877e-17 -0.0050000000000000079103" rpy="0 0 0"/>
<mass value="0.023029890215175794627" />
<inertia ixx="3.9323633187538940061e-06" ixy="-5.4572503720899570435e-22"  ixz="8.3054620224859692161e-22" iyy="3.932363318753891465e-06" iyz="5.9899235881624067891e-23" izz="7.4808951339215225593e-06" />
</inertial>
</link>

<joint name="arm_wrist2_mount" type="fixed">
<origin xyz="-5.5511151231257827021e-17 -8.3266726846886740532e-17 0.015000000000000068834" rpy="3.1415926535897917837 -0 3.3306690738754720865e-16" />
<parent link="link_armlast" />
<child link="link_armlast2" />
<axis xyz="0 0 1"/>
<limit effort="1" velocity="20" />
<joint_properties friction="0.0"/>
</joint>

<joint name="arm_wrist3" type="revolute">
<origin xyz="0.041264886036515013856 -1.1102230246251565404e-16 -0.013174576908349888704" rpy="-1.5707963267948934494 -1.3594921570126590193 -1.5707963267948779063" />
<parent link="link_arm_wrist2" />
<child link="link_armlast" />
<axis xyz="0 0 1"/>
<limit effort="1" velocity="20" lower="-1.570796326794896558" upper="1.570796326794896558"/>
<joint_properties friction="0.0"/>
</joint>

<joint name="arm_wrist2" type="revolute">
<origin xyz="0.015999999999999847677 0 0.034299999999999830624" rpy="-1.5707963267949154318 -1.5412222261540717838 -1.570796326794483555" />
<parent link="link_wrist_end" />
<child link="link_arm_wrist2" />
<axis xyz="0 0 1"/>
<limit effort="1" velocity="20" lower="-1.2217304763960306069" upper="1.2217304763960306069"/>
<joint_properties friction="0.0"/>
</joint>

<joint name="arm_wrist_fix_mount" type="fixed">
<origin xyz="1.6653345369377348106e-16 0 -0.018200000000000049472" rpy="-3.1415926535897904515 -1.1657341758564118036e-15 -1.5707963267948974462" />
<parent link="link_wrist_base" />
<child link="link_wrist_end" />
<axis xyz="0 0 1"/>
<limit effort="1" velocity="20" />
<joint_properties friction="0.0"/>
</joint>

<joint name="arm_wrist1" type="revolute">
<origin xyz="-5.5511151231257827021e-17 0 1.6653345369377348106e-16" rpy="3.1415926535897895633 -1.1102230246251612243e-16 -2.4609741910012123967" />
<parent link="link_wrist_base_bearing" />
<child link="link_wrist_base" />
<axis xyz="0 0 1"/>
<limit effort="1" velocity="20" lower="-3.141592653589793116" upper="3.141592653589793116"/>
<joint_properties friction="0.0"/>
</joint>

<joint name="arm_wrist_bearing_mount" type="revolute">
<origin xyz="-1.1102230246251565404e-16 0.023400000000000031886 0.016000000000000041966" rpy="1.570796326794896336 -0.45412831300399308931 -3.1415926535897904515" />
<parent link="link_wrist_mid" />
<child link="link_wrist_base_bearing" />
<axis xyz="0 0 1"/>
<limit effort="1" velocity="20" lower="-3.141592653589793116" upper="3.141592653589793116"/>
<joint_properties friction="0.0"/>
</joint>

<joint name="link3_fix_wrist" type="fixed">
<origin xyz="-5.5511151231257827021e-17 -0.16999999999999998446 -4.1633363423443370266e-17" rpy="-3.1415926535897806815 -1.5939872126258999345e-16 2.7755575615628169023e-16" />
<parent link="link_arm4" />
<child link="link_wrist_mid" />
<axis xyz="0 0 1"/>
<limit effort="1" velocity="20" />
<joint_properties friction="0.0"/>
</joint>

<joint name="link2" type="revolute">
<origin xyz="8.066464163292152989e-17 0.13846826553344721011 -0.041000000000000161315" rpy="3.1415926535897913396 9.1972345972029474466e-15 -1.3852139784755002072" />
<parent link="link_arm3" />
<child link="link_arm4" />
<axis xyz="0 0 1"/>
<limit effort="1" velocity="20" lower="-1.7453292519943295336" upper="2.4434609527920612138"/>
<joint_properties friction="0.0"/>
</joint>

<joint name="link1.5" type="revolute">
<origin xyz="-0.043380152669139998567 -0.020000000000000045519 -0.066448956727981622894" rpy="-1.5707963267948976682 -0.81088336103405489474 -3.1415926535897891192" />
<parent link="link_arm2" />
<child link="link_arm3" />
<axis xyz="0 0 1"/>
<limit effort="1" velocity="20" lower="-1.7453292519943295336" upper="1.0471975511965976313"/>
<joint_properties friction="0.0"/>
</joint>

<joint name="arm_link2_mount2" type="fixed">
<origin xyz="0 -2.7755575615628913511e-17 -0.015000000000000013323" rpy="-5.2284285563078351932e-17 6.3131392702426513487e-17 -3.1415926535897926719" />
<parent link="link_arm1_top_mount" />
<child link="link_arm2" />
<axis xyz="0 0 1"/>
<limit effort="1" velocity="20" />
<joint_properties friction="0.0"/>
</joint>

<joint name="arm_base_mount" type="fixed">
<origin xyz="-1.0130785099704553431e-15 -5.5511151231257827021e-17 -0.024999999999999966693" rpy="2.4768215088350958508e-17 1.5777218104419826228e-30 -1.5707963267948972241" />
<parent link="link_arm1_bearing" />
<child link="link_arm1_top_mount" />
<axis xyz="0 0 1"/>
<limit effort="1" velocity="20" />
<joint_properties friction="0.0"/>
</joint>

<joint name="arm_base1" type="revolute">
<origin xyz="-0.067724570631980868241 -3.6429192995512948983e-17 0.0065000000000000335287" rpy="1.5626452826491723369e-15 5.9797388244350604472e-16 -2.1628522376395276083" />
<parent link="link_arm1_base" />
<child link="link_arm1_bearing" />
<axis xyz="0 0 1"/>
<limit effort="1" velocity="20" lower="-2.0943951023931952626" upper="2.0943951023931952626"/>
<joint_properties friction="0.0"/>
</joint>

<joint name="arm_link2_mount" type="fixed">
<origin xyz="0.067724570631980868241 1.7347234759768070944e-18 -0.025000000000000022204" rpy="1.110223223148592793e-16 8.628166150854805674e-32 2.0272338594620006054e-30" />
<parent link="link_arm1" />
<child link="link_arm1_base" />
<axis xyz="0 0 1"/>
<limit effort="1" velocity="20" />
<joint_properties friction="0.0"/>
</joint>

<joint name="arm_bearing_mount" type="fixed">
<origin xyz="0.035003417238566127134 -0.080546758170579296765 0" rpy="-3.141592653589793116 1.7256332301709504061e-31 1.570796326794896558" />
<parent link="link_arm_mount_base" />
<child link="link_arm1" />
<axis xyz="0 0 1"/>
<limit effort="1" velocity="20" />
<joint_properties friction="0.0"/>
</joint>

<link name="link_base">
<visual>
<origin xyz="8.6736173798840354721e-19 0.21544027328491210938 -0.040000000000000000833" rpy="0 -1.5407439555097886824e-33 1.1555579666323338143e-33" />
<geometry>
<mesh filename="package://nashbot/description/link_base.stl"/>
</geometry>
<material name="link_base_material">
<color rgba="0.90196078431372550543 0.87843137254901959565 0.81176470588235294379 1.0"/>
</material>
</visual>
<collision>
<origin xyz="8.6736173798840354721e-19 0.21544027328491210938 -0.040000000000000000833" rpy="0 -1.5407439555097886824e-33 1.1555579666323338143e-33" />
<geometry>
<mesh filename="package://nashbot/description/link_base.stl"/>
</geometry>
</collision>
<inertial>
<origin xyz="0.0025929182775734993874 0.21461487351882460595 -0.019693145491013395315" rpy="0 0 0"/>
<mass value="6.92419794483562967" />
<inertia ixx="0.15317371308121469076" ixy="0.00026141418817127030135"  ixz="-5.9672159842200201734e-07" iyy="0.14817521999467025973" iyz="-7.1120897181438903871e-07" izz="0.29927189175921442565" />
</inertial>
</link>

<link name="link_lidar_pole_mount">
<visual>
<origin xyz="0 0 0" rpy="3.141592653589793116 -0 0" />
<geometry>
<mesh filename="package://nashbot/description/link_lidar_pole_mount.stl"/>
</geometry>
<material name="link_lidar_pole_mount_material">
<color rgba="1 0 0 1.0"/>
</material>
</visual>
<collision>
<origin xyz="0 0 0" rpy="3.141592653589793116 -0 0" />
<geometry>
<mesh filename="package://nashbot/description/link_lidar_pole_mount.stl"/>
</geometry>
</collision>
<inertial>
<origin xyz="-2.6596614645950761366e-19 -2.9258108851844994997e-18 -0.024999999999999997918" rpy="0 0 0"/>
<mass value="0.0049087385212340526111" />
<inertia ixx="1.0533334743481403072e-06" ixy="2.9212509307138273085e-38"  ixz="0" iyy="1.0533334743481403072e-06" iyz="0" izz="6.135923151542562776e-08" />
</inertial>
</link>

<link name="link_lidar_base_mount">
<visual>
<origin xyz="-0.00023304969072342543446 -0.06782839000225068804 -0.009999999999999995004" rpy="0 3.4211388289180104271e-49 0" />
<geometry>
<mesh filename="package://nashbot/description/link_lidar_base_mount.stl"/>
</geometry>
<material name="link_lidar_base_mount_material">
<color rgba="0.19607843137254901689 0.43921568627450979783 0.078431372549019606755 1.0"/>
</material>
</visual>
<collision>
<origin xyz="-0.00023304969072342543446 -0.06782839000225068804 -0.009999999999999995004" rpy="0 3.4211388289180104271e-49 0" />
<geometry>
<mesh filename="package://nashbot/description/link_lidar_base_mount.stl"/>
</geometry>
</collision>
<inertial>
<origin xyz="-9.053088140253962024e-18 -1.3877787807814456755e-17 -0.0049999999999999948999" rpy="0 0 0"/>
<mass value="0.12500000000000002776" />
<inertia ixx="0.00010520833333333332016" ixy="-4.2956262467936565252e-36"  ixz="-3.5993231429241563529e-53" iyy="0.00010520833333333334727" iyz="0" izz="0.00020833333333333334671" />
</inertial>
</link>

<link name="link_lidar">
<visual>
<origin xyz="0 -3.4694469519536141888e-18 -0.040000000000000035527" rpy="0 -0 0" />
<geometry>
<mesh filename="package://nashbot/description/link_lidar.stl"/>
</geometry>
<material name="link_lidar_material">
<color rgba="0 0 0 1.0"/>
</material>
</visual>
<collision>
<origin xyz="0 -3.4694469519536141888e-18 -0.040000000000000035527" rpy="0 -0 0" />
<geometry>
<mesh filename="package://nashbot/description/link_lidar.stl"/>
</geometry>
</collision>
<inertial>
<origin xyz="-8.7708866231685953244e-19 -7.1399165387206892957e-19 -0.020000000000000035111" rpy="0 0 0"/>
<mass value="0.31808625617596653079" />
<inertia ixx="0.00020344266801254528502" ixy="1.8023551009404287405e-35"  ixz="0" iyy="0.00020344266801254523081" iyz="0" izz="0.00032206233437816612734" />
</inertial>
</link>

<joint name="lidar_base" type="fixed">
<origin xyz="0 0 -0.0099999999999999672484" rpy="9.2981178312356308058e-16 2.775557561562880874e-17 -1.57079632679489678" />
<parent link="link_lidar_base_mount" />
<child link="link_lidar" />
<axis xyz="0 0 1"/>
<limit effort="1" velocity="20" />
<joint_properties friction="0.0"/>
</joint>

<joint name="lidar_plate" type="fixed">
<origin xyz="0 0 -0.050000000000000002776" rpy="-9.7144514654698337666e-16 6.8755699014622677807e-32 7.2858385991024727e-17" />
<parent link="link_lidar_pole_mount" />
<child link="link_lidar_base_mount" />
<axis xyz="0 0 1"/>
<limit effort="1" velocity="20" />
<joint_properties friction="0.0"/>
</joint>

<joint name="lidar_mount" type="fixed">
<origin xyz="0.0037285491515770411222 0.24401362636184925625 0" rpy="-3.1415926535897922278 1.3877787807814401289e-17 1.3877787807814435185e-17" />
<parent link="link_base" />
<child link="link_lidar_pole_mount" />
<axis xyz="0 0 1"/>
<limit effort="1" velocity="20" />
<joint_properties friction="0.0"/>
</joint>

<link name="link_camera_pole">
<visual>
<origin xyz="0 0 0" rpy="3.141592653589793116 -0 7.7037197775487757764e-34" />
<geometry>
<mesh filename="package://nashbot/description/link_camera_pole.stl"/>
</geometry>
<material name="link_camera_pole_material">
<color rgba="0.047058823529411764053 0.47058823529411764053 0.43529411764705883137 1.0"/>
</material>
</visual>
<collision>
<origin xyz="0 0 0" rpy="3.141592653589793116 -0 7.7037197775487757764e-34" />
<geometry>
<mesh filename="package://nashbot/description/link_camera_pole.stl"/>
</geometry>
</collision>
<inertial>
<origin xyz="-8.6895599421206154125e-19 -1.1332899522663488711e-18 -0.19999999999999998335" rpy="0 0 0"/>
<mass value="0.15707963267948968356" />
<inertia ixx="0.002098322093210182749" ixy="-6.4659541636568506617e-35"  ixz="0" iyy="0.002098322093210182749" iyz="-4.8403898916924359354e-38" izz="7.8539816339744905176e-06" />
</inertial>
</link>

<link name="link_camera_servo1">
<visual>
<origin xyz="-0.038404866796954761909 0.0050000000000000001041 -0.061967622488737106323" rpy="1.570796326794896558 1.570796326794896558 0" />
<geometry>
<mesh filename="package://nashbot/description/link_camera_servo1.stl"/>
</geometry>
<material name="link_camera_servo1_material">
<color rgba="0.64705882352941179736 0.64705882352941179736 0.64705882352941179736 1.0"/>
</material>
</visual>
<collision>
<origin xyz="-0.038404866796954761909 0.0050000000000000001041 -0.061967622488737106323" rpy="1.570796326794896558 1.570796326794896558 0" />
<geometry>
<mesh filename="package://nashbot/description/link_camera_servo1.stl"/>
</geometry>
</collision>
<inertial>
<origin xyz="-0.005531869657899125825 0 -0.0076559257720910725564" rpy="0 0 0"/>
<mass value="0.0031040514451390215957" />
<inertia ixx="8.3234670146980132766e-08" ixy="3.4622262357068703335e-36"  ixz="2.6774338660596833796e-09" iyy="1.3095099196449408934e-07" iyz="-1.6187231168523716084e-37" izz="1.0058054508357338887e-07" />
</inertial>
</link>

<link name="link_camera_servo2">
<visual>
<origin xyz="-0.0006048667969547408263 0.0050000000000001154632 -0.061967622488737106323" rpy="1.570796326794896558 1.570796326794896558 0" />
<geometry>
<mesh filename="package://nashbot/description/link_camera_servo2.stl"/>
</geometry>
<material name="link_camera_servo2_material">
<color rgba="0.64705882352941179736 0.64705882352941179736 0.64705882352941179736 1.0"/>
</material>
</visual>
<collision>
<origin xyz="-0.0006048667969547408263 0.0050000000000001154632 -0.061967622488737106323" rpy="1.570796326794896558 1.570796326794896558 0" />
<geometry>
<mesh filename="package://nashbot/description/link_camera_servo2.stl"/>
</geometry>
</collision>
<inertial>
<origin xyz="-0.0055318696578990980695 1.1622647289044607533e-16 -0.0076559257720910725564" rpy="0 0 0"/>
<mass value="0.0031040514451390215957" />
<inertia ixx="8.3234670146980159236e-08" ixy="2.5576780277937545202e-26"  ixz="2.677433866059682966e-09" iyy="1.3095099196449406288e-07" iyz="1.2559377407435970818e-24" izz="1.0058054508357337563e-07" />
</inertial>
</link>

<link name="link_camera">
<visual>
<origin xyz="0.035000000000000003331 -0.012000000000000066169 -0.024999999999999994449" rpy="-2.7755575615628913511e-17 1.4845213134904354474e-17 -2.7350958769985757155e-18" />
<geometry>
<mesh filename="package://nashbot/description/link_camera.stl"/>
</geometry>
<material name="link_camera_material">
<color rgba="0.34901960784313723618 0.37647058823529411242 0.4000000000000000222 1.0"/>
</material>
</visual>
<collision>
<origin xyz="0.035000000000000003331 -0.012000000000000066169 -0.024999999999999994449" rpy="-2.7755575615628913511e-17 1.4845213134904354474e-17 -2.7350958769985757155e-18" />
<geometry>
<mesh filename="package://nashbot/description/link_camera.stl"/>
</geometry>
</collision>
<inertial>
<origin xyz="6.9388939039072283776e-18 -6.9640155378572689622e-17 -0.012499999999999993755" rpy="0 0 0"/>
<mass value="0.38900054186990395966" />
<inertia ixx="3.8154949126898210759e-05" ixy="6.1489496330894238962e-22"  ixz="4.0872263266589556595e-22" iyy="0.00025036725930444205098" iyz="-1.3832506749957487835e-20" izz="0.00024800131865322530642" />
</inertial>
</link>

<joint name="camera_pole" type="fixed">
<origin xyz="-0.013887045648916858387 5.5511151231257827021e-17 -0.0075000000000000049266" rpy="-3.1415926535897917837 -1.5707963267948943376 0" />
<parent link="link_camera_servo2" />
<child link="link_camera" />
<axis xyz="0 0 1"/>
<limit effort="1" velocity="20" />
<joint_properties friction="0.0"/>
</joint>

<joint name="camera_mount2" type="revolute">
<origin xyz="-0.0053870456489168022651 0.0049999999999999740832 -0.0075000000000002842171" rpy="1.570796326794896558 -0.25065267009427094624 -1.83260399496375333e-15" />
<parent link="link_camera_servo1" />
<child link="link_camera_servo2" />
<axis xyz="0 0 1"/>
<limit effort="1" velocity="20" lower="-0.52359877559829881566" upper="1.570796326794896558"/>
<joint_properties friction="0.0"/>
</joint>

<joint name="camera_mount1" type="revolute">
<origin xyz="1.3877787807814456755e-17 2.7755575615628913511e-17 -0.4000000000000000222" rpy="7.9969164658563554825e-15 -2.2107962561891007614e-15 -1.3373694162135525421" />
<parent link="link_camera_pole" />
<child link="link_camera_servo1" />
<axis xyz="0 0 1"/>
<limit effort="1" velocity="20" lower="-1.570796326794896558" upper="1.570796326794896558"/>
<joint_properties friction="0.0"/>
</joint>

<joint name="camera_mount" type="fixed">
<origin xyz="0.0037285491515770341833 0.31121362636184918271 0" rpy="-3.141592653589793116 1.6640034719505514144e-31 -1.387778780781409468e-17" />
<parent link="link_base" />
<child link="link_camera_pole" />
<axis xyz="0 0 1"/>
<limit effort="1" velocity="20" />
<joint_properties friction="0.0"/>
</joint>

<link name="link_wheels">
<visual>
<origin xyz="0 0 -0.024999999999999966693" rpy="-1.570796326794896558 -1.232595164407830946e-31 -6.9388939039072283776e-18" />
<geometry>
<mesh filename="package://nashbot/description/link_wheels.stl"/>
</geometry>
<material name="link_wheels_material">
<color rgba="0 0 0 1.0"/>
</material>
</visual>
<collision>
<origin xyz="0 0 -0.024999999999999966693" rpy="-1.570796326794896558 -1.232595164407830946e-31 -6.9388939039072283776e-18" />
<geometry>
<mesh filename="package://nashbot/description/link_wheels.stl"/>
</geometry>
</collision>
<inertial>
<origin xyz="-1.7429912632529263056e-18 4.0728523192345737126e-18 -0.012499999999999964265" rpy="0 0 0"/>
<mass value="0.20449411980379361697" />
<inertia ixx="0.00013973764853259228744" ixy="-9.6962471754913548028e-22"  ixz="2.3339858831586061826e-35" iyy="0.00013973764853259231455" iyz="-1.1951547381413731984e-52" izz="0.00025817382625228945704" />
</inertial>
</link>

<joint name="wheel1_right" type="continuous">
<origin xyz="-0.24999999999999991673 0.21551037962490227073 -0.061455325186252587888" rpy="-1.570796326794896558 -0.040746602626920307155 -1.5707963267949009989" />
<parent link="link_base" />
<child link="link_wheels" />
<axis xyz="0 0 1"/>
<limit effort="1" velocity="20" />
<joint_properties friction="0.0"/>
</joint>

<link name="link_wheels_2">
<visual>
<origin xyz="1.7347234759768070944e-18 0 -0.025000000000000022204" rpy="-1.570796326794896558 -0 0" />
<geometry>
<mesh filename="package://nashbot/description/link_wheels.stl"/>
</geometry>
<material name="link_wheels_material">
<color rgba="0 0 0 1.0"/>
</material>
</visual>
<collision>
<origin xyz="1.7347234759768070944e-18 0 -0.025000000000000022204" rpy="-1.570796326794896558 -0 0" />
<geometry>
<mesh filename="package://nashbot/description/link_wheels.stl"/>
</geometry>
</collision>
<inertial>
<origin xyz="-8.2677872761201742017e-21 4.0728523192345737126e-18 -0.012500000000000019776" rpy="0 0 0"/>
<mass value="0.20449411980379361697" />
<inertia ixx="0.00013973764853259228744" ixy="-1.5513995480786170694e-20"  ixz="-2.386678573614333034e-36" iyy="0.00013973764853259231455" iyz="3.340818317239160126e-34" izz="0.00025817382625228945704" />
</inertial>
</link>

<joint name="wheel2_left" type="continuous">
<origin xyz="0.24999999999999986122 0.21551037962490224298 -0.061455325186252726666" rpy="-1.570796326794896558 1.201710438508162504 1.5707963267949349717" />
<parent link="link_base" />
<child link="link_wheels_2" />
<axis xyz="0 0 1"/>
<limit effort="1" velocity="20" />
<joint_properties friction="0.0"/>
</joint>

<link name="t_2-2_mouting_plate">
<visual>
<origin xyz="0 0 -0.0012922249999999975423" rpy="1.570796326794896558 -0 -1.07852076885930435e-32" />
<geometry>
<mesh filename="package://nashbot/description/t_2-2_mouting_plate.stl"/>
</geometry>
<material name="t_2-2_mouting_plate_material">
<color rgba="0.79607843137254896693 0.82352941176470584317 0.9372549019607843146 1.0"/>
</material>
</visual>
<collision>
<origin xyz="0 0 -0.0012922249999999975423" rpy="1.570796326794896558 -0 -1.07852076885930435e-32" />
<geometry>
<mesh filename="package://nashbot/description/t_2-2_mouting_plate.stl"/>
</geometry>
</collision>
<inertial>
<origin xyz="3.4038446122876661915e-19 -5.1057669184314990465e-19 -0.0012922249999999975423" rpy="0 0 0"/>
<mass value="0.038153138865978875049" />
<inertia ixx="3.0092952259066954834e-06" ixy="4.527788978094434109e-39"  ixz="0" iyy="1.2001884821145976089e-05" iyz="0" izz="1.4968706816811058283e-05" />
</inertial>
</link>

<link name="t_2-3_bracket">
<visual>
<origin xyz="-0.045486319999999996755 0 -3.4694469519536141888e-18" rpy="1.570796326794896558 1.1067045288563090553e-19 -1.0785207688592518013e-32" />
<geometry>
<mesh filename="package://nashbot/description/t_2-3_bracket.stl"/>
</geometry>
<material name="t_2-3_bracket_material">
<color rgba="0.79607843137254896693 0.82352941176470584317 0.9372549019607843146 1.0"/>
</material>
</visual>
<collision>
<origin xyz="-0.045486319999999996755 0 -3.4694469519536141888e-18" rpy="1.570796326794896558 1.1067045288563090553e-19 -1.0785207688592518013e-32" />
<geometry>
<mesh filename="package://nashbot/description/t_2-3_bracket.stl"/>
</geometry>
</collision>
<inertial>
<origin xyz="8.3566322151097660598e-05 -5.7832354076524236399e-20 -0.020996006880772095232" rpy="0 0 0"/>
<mass value="0.030960253599026488214" />
<inertia ixx="4.5924729635141938288e-06" ixy="-1.0778385845226896638e-37"  ixz="-2.4512710256687426414e-06" iyy="9.4662576262463151973e-06" iyz="2.6437467112866588691e-38" izz="4.9083136439462329159e-06" />
</inertial>
</link>

<link name="t_2-6_pin">
<visual>
<origin xyz="0 -8.6736173798840354721e-19 -0.011630024999999988289" rpy="0 6.1629758220200073e-33 0" />
<geometry>
<mesh filename="package://nashbot/description/t_2-6_pin.stl"/>
</geometry>
<material name="t_2-6_pin_material">
<color rgba="0.79607843137254896693 0.82352941176470584317 0.9372549019607843146 1.0"/>
</material>
</visual>
<collision>
<origin xyz="0 -8.6736173798840354721e-19 -0.011630024999999988289" rpy="0 6.1629758220200073e-33 0" />
<geometry>
<mesh filename="package://nashbot/description/t_2-6_pin.stl"/>
</geometry>
</collision>
<inertial>
<origin xyz="5.6932821335017661018e-20 -8.6736173798840354721e-19 -0.011630024999999988289" rpy="0 0 0"/>
<mass value="0.015325915748070038924" />
<inertia ixx="7.9334923134588077871e-07" ixy="0"  ixz="-7.0975047065878349978e-39" iyy="7.9334923134588077871e-07" iyz="0" izz="2.047352855086143151e-07" />
</inertial>
</link>

<link name="t_2-4_wheel">
<visual>
<origin xyz="0 0 0" rpy="-3.141592653589793116 -0 0" />
<geometry>
<mesh filename="package://nashbot/description/t_2-4_wheel.stl"/>
</geometry>
<material name="t_2-4_wheel_material">
<color rgba="0.79607843137254896693 0.82352941176470584317 0.9372549019607843146 1.0"/>
</material>
</visual>
<collision>
<origin xyz="0 0 0" rpy="-3.141592653589793116 -0 0" />
<geometry>
<mesh filename="package://nashbot/description/t_2-4_wheel.stl"/>
</geometry>
</collision>
<inertial>
<origin xyz="-1.3050080262776051415e-16 8.5719917726490599603e-17 1.4099350065041936117e-19" rpy="0 0 0"/>
<mass value="0.18421750729180022543" />
<inertia ixx="5.3329604133002573056e-05" ixy="1.3146762434824454187e-36"  ixz="1.5698240935883667127e-68" iyy="5.3329604133002105493e-05" iyz="1.8883443628591925191e-36" izz="0.00010153764135718144803" />
</inertial>
</link>

<link name="t_2-5_tire">
<visual>
<origin xyz="0 0 0" rpy="1.570796326794896558 1.570796326794896558 0" />
<geometry>
<mesh filename="package://nashbot/description/t_2-5_tire.stl"/>
</geometry>
<material name="t_2-5_tire_material">
<color rgba="0.30196078431372547213 0.30196078431372547213 0.30196078431372547213 1.0"/>
</material>
</visual>
<collision>
<origin xyz="0 0 0" rpy="1.570796326794896558 1.570796326794896558 0" />
<geometry>
<mesh filename="package://nashbot/description/t_2-5_tire.stl"/>
</geometry>
</collision>
<inertial>
<origin xyz="-2.444280074908681738e-50 9.9151779330684541727e-19 2.0782392108461292163e-17" rpy="0 0 0"/>
<mass value="0.01273663756489323666" />
<inertia ixx="6.6799078269866379528e-06" ixy="-1.646724417246752858e-37"  ixz="-1.9663150365040675875e-69" iyy="6.6799078269866481172e-06" iyz="2.3862623993848018476e-37" izz="1.2888499855052773049e-05" />
</inertial>
</link>

<joint name="caster_wheel" type="fixed">
<origin xyz="0 0 0" rpy="-3.141592653589793116 -0 0" />
<parent link="t_2-4_wheel" />
<child link="t_2-5_tire" />
<axis xyz="0 0 1"/>
<limit effort="1" velocity="20" />
<joint_properties friction="0.0"/>
</joint>

<joint name="caster_inner_axle" type="continuous">
<origin xyz="1.3877787807814456755e-17 -8.6736173798840354721e-19 -0.011630024999999988289" rpy="3.141592653589793116 2.7755575615629246311e-17 1.570796326794896558" />
<parent link="t_2-6_pin" />
<child link="t_2-4_wheel" />
<axis xyz="0 0 1"/>
<limit effort="1" velocity="20" />
<joint_properties friction="0.0"/>
</joint>

<joint name="caster_axle" type="continuous">
<origin xyz="-0.019641819999999997337 0 -0.036182300000000000573" rpy="1.570796326794896558 -1.3877677137361563236e-14 -3.1225022567581769653e-17" />
<parent link="t_2-3_bracket" />
<child link="t_2-6_pin" />
<axis xyz="0 0 1"/>
<limit effort="1" velocity="20" />
<joint_properties friction="0.0"/>
</joint>

<joint name="caster_shaft" type="fixed">
<origin xyz="-0.020675599999999988432 -0.010337800000000008094 -0.0025844499999999742679" rpy="-5.5511151231262005519e-17 -1.1067045303393603349e-19 -3.4694469519546380132e-18" />
<parent link="t_2-2_mouting_plate" />
<child link="t_2-3_bracket" />
<axis xyz="0 0 1"/>
<limit effort="1" velocity="20" />
<joint_properties friction="0.0"/>
</joint>

<link name="t_2-3_bracket_2">
<visual>
<origin xyz="-0.045486319999999996755 0 0" rpy="1.570796326794896558 1.1067045288563090553e-19 -1.0785207688592518013e-32" />
<geometry>
<mesh filename="package://nashbot/description/t_2-3_bracket.stl"/>
</geometry>
<material name="t_2-3_bracket_material">
<color rgba="0.79607843137254896693 0.82352941176470584317 0.9372549019607843146 1.0"/>
</material>
</visual>
<collision>
<origin xyz="-0.045486319999999996755 0 0" rpy="1.570796326794896558 1.1067045288563090553e-19 -1.0785207688592518013e-32" />
<geometry>
<mesh filename="package://nashbot/description/t_2-3_bracket.stl"/>
</geometry>
</collision>
<inertial>
<origin xyz="8.3566322151097660598e-05 -5.7832354076524236399e-20 -0.020996006880772091763" rpy="0 0 0"/>
<mass value="0.030960253599026488214" />
<inertia ixx="4.5924729635141938288e-06" ixy="-1.0778385845226896638e-37"  ixz="-2.4512710256687426414e-06" iyy="9.4662576262463151973e-06" iyz="2.6437467112866588691e-38" izz="4.9083136439462329159e-06" />
</inertial>
</link>

<joint name="caster_shaft2" type="fixed">
<origin xyz="-0.020675599999999988432 0.010337800000000035849 -0.0025844499999999742679" rpy="-5.5511151231262005519e-17 -1.1067045303393603349e-19 -3.4694469519546380132e-18" />
<parent link="t_2-2_mouting_plate" />
<child link="t_2-3_bracket_2" />
<axis xyz="0 0 1"/>
<limit effort="1" velocity="20" />
<joint_properties friction="0.0"/>
</joint>

<joint name="caster_base_mount" type="continuous">
<origin xyz="-8.6736173798840354721e-18 0.43091411888599395752 -0.039999999999999986955" rpy="5.5511151231256791641e-17 1.4058199049316279774e-14 1.7694179454963328825e-16" />
<parent link="link_base" />
<child link="t_2-2_mouting_plate" />
<axis xyz="0 0 1"/>
<limit effort="1" velocity="20" />
<joint_properties friction="0.0"/>
</joint>

<link name="t_2-2_mouting_plate_2">
<visual>
<origin xyz="2.7755575615628913511e-17 -3.4694469519536141888e-18 -0.0012922250000000010117" rpy="1.570796326794896558 1.9721522630525295135e-31 8.2844144989323925463e-30" />
<geometry>
<mesh filename="package://nashbot/description/t_2-2_mouting_plate.stl"/>
</geometry>
<material name="t_2-2_mouting_plate_material">
<color rgba="0.79607843137254896693 0.82352941176470584317 0.9372549019607843146 1.0"/>
</material>
</visual>
<collision>
<origin xyz="2.7755575615628913511e-17 -3.4694469519536141888e-18 -0.0012922250000000010117" rpy="1.570796326794896558 1.9721522630525295135e-31 8.2844144989323925463e-30" />
<geometry>
<mesh filename="package://nashbot/description/t_2-2_mouting_plate.stl"/>
</geometry>
</collision>
<inertial>
<origin xyz="2.80959600768576796e-17 -3.9800236437967640935e-18 -0.0012922250000000010117" rpy="0 0 0"/>
<mass value="0.038153138865978875049" />
<inertia ixx="3.0092952259066954834e-06" ixy="-3.3311922168326270493e-22"  ixz="-5.9347883899650625387e-37" iyy="1.20018848211459727e-05" iyz="-4.9166246985922191391e-66" izz="1.4968706816811058283e-05" />
</inertial>
</link>

<link name="t_2-3_bracket_3">
<visual>
<origin xyz="-0.045486319999999968999 0 0" rpy="1.570796326794896558 1.1067045288622257528e-19 8.4757502241068892055e-30" />
<geometry>
<mesh filename="package://nashbot/description/t_2-3_bracket.stl"/>
</geometry>
<material name="t_2-3_bracket_material">
<color rgba="0.79607843137254896693 0.82352941176470584317 0.9372549019607843146 1.0"/>
</material>
</visual>
<collision>
<origin xyz="-0.045486319999999968999 0 0" rpy="1.570796326794896558 1.1067045288622257528e-19 8.4757502241068892055e-30" />
<geometry>
<mesh filename="package://nashbot/description/t_2-3_bracket.stl"/>
</geometry>
</collision>
<inertial>
<origin xyz="8.3566322151118477279e-05 -5.7832354076137497629e-20 -0.020996006880772091763" rpy="0 0 0"/>
<mass value="0.030960253599026488214" />
<inertia ixx="4.5924729635141921347e-06" ixy="1.1650242566680388526e-34"  ixz="-2.4512710256687422179e-06" iyy="9.4662576262463118092e-06" iyz="-3.5711482065350515578e-35" izz="4.9083136439462329159e-06" />
</inertial>
</link>

<link name="t_2-6_pin_2">
<visual>
<origin xyz="-2.7755575615628913511e-17 0 -0.011630025000000002167" rpy="0 2.7755575615711127608e-17 -1.5777218104420239611e-30" />
<geometry>
<mesh filename="package://nashbot/description/t_2-6_pin.stl"/>
</geometry>
<material name="t_2-6_pin_material">
<color rgba="0.79607843137254896693 0.82352941176470584317 0.9372549019607843146 1.0"/>
</material>
</visual>
<collision>
<origin xyz="-2.7755575615628913511e-17 0 -0.011630025000000002167" rpy="0 2.7755575615711127608e-17 -1.5777218104420239611e-30" />
<geometry>
<mesh filename="package://nashbot/description/t_2-6_pin.stl"/>
</geometry>
</collision>
<inertial>
<origin xyz="-2.7698642794293894465e-17 -8.9824153950256331785e-50 -0.011630025000000002167" rpy="0 0 0"/>
<mass value="0.015325915748070038924" />
<inertia ixx="7.9334923134588056696e-07" ixy="-1.2516843855918106831e-36"  ixz="-2.2019864580303898991e-23" iyy="7.9334923134588077871e-07" iyz="3.4741220611298421812e-53" izz="2.047352855086143151e-07" />
</inertial>
</link>

<link name="t_2-4_wheel_2">
<visual>
<origin xyz="-1.3877787807814456755e-17 -2.7755575615628913511e-17 -3.4694469519536141888e-18" rpy="-3.141592653589793116 1.5808348259625381109e-17 0" />
<geometry>
<mesh filename="package://nashbot/description/t_2-4_wheel.stl"/>
</geometry>
<material name="t_2-4_wheel_material">
<color rgba="0.79607843137254896693 0.82352941176470584317 0.9372549019607843146 1.0"/>
</material>
</visual>
<collision>
<origin xyz="-1.3877787807814456755e-17 -2.7755575615628913511e-17 -3.4694469519536141888e-18" rpy="-3.141592653589793116 1.5808348259625381109e-17 0" />
<geometry>
<mesh filename="package://nashbot/description/t_2-4_wheel.stl"/>
</geometry>
</collision>
<inertial>
<origin xyz="-1.4437859043557497091e-16 5.7964342110861686092e-17 -3.3284534513031895554e-18" rpy="0 0 0"/>
<mass value="0.18421750729180022543" />
<inertia ixx="5.3329604133002573056e-05" ixy="5.9207754402603846581e-21"  ixz="1.409246540259376663e-21" iyy="5.3329604133002105493e-05" iyz="4.7403845889616828996e-21" izz="0.00010153764135718142093" />
</inertial>
</link>

<link name="t_2-5_tire_2">
<visual>
<origin xyz="-1.3877787807814456755e-17 2.7755575615628913511e-17 6.9388939039072283776e-18" rpy="1.570796326794896558 1.570796326794896558 0" />
<geometry>
<mesh filename="package://nashbot/description/t_2-5_tire.stl"/>
</geometry>
<material name="t_2-5_tire_material">
<color rgba="0.30196078431372547213 0.30196078431372547213 0.30196078431372547213 1.0"/>
</material>
</visual>
<collision>
<origin xyz="-1.3877787807814456755e-17 2.7755575615628913511e-17 6.9388939039072283776e-18" rpy="1.570796326794896558 1.570796326794896558 0" />
<geometry>
<mesh filename="package://nashbot/description/t_2-5_tire.stl"/>
</geometry>
</collision>
<inertial>
<origin xyz="-1.3877787807814456755e-17 2.8747093408935757772e-17 2.7721286012368517459e-17" rpy="0 0 0"/>
<mass value="0.01273663756489323666" />
<inertia ixx="6.6799078269866379528e-06" ixy="-7.4161874718943733478e-22"  ixz="-1.8029331994222556616e-22" iyy="6.6799078269866481172e-06" iyz="5.985549585875497884e-22" izz="1.2888499855052769661e-05" />
</inertial>
</link>

<joint name="caster_wheel2" type="fixed">
<origin xyz="-1.3877787807814456755e-17 -2.7755575615628913511e-17 0" rpy="-3.141592653589793116 1.5808348259625381109e-17 0" />
<parent link="t_2-4_wheel_2" />
<child link="t_2-5_tire_2" />
<axis xyz="0 0 1"/>
<limit effort="1" velocity="20" />
<joint_properties friction="0.0"/>
</joint>

<joint name="caster_inner_axle2" type="continuous">
<origin xyz="-2.7755575615628913511e-17 0 -0.011630025000000002167" rpy="3.1415926535897926719 5.3790483572030952479e-16 -2.2447468074446286224" />
<parent link="t_2-6_pin_2" />
<child link="t_2-4_wheel_2" />
<axis xyz="0 0 1"/>
<limit effort="1" velocity="20" />
<joint_properties friction="0.0"/>
</joint>

<joint name="caster_axle2" type="continuous">
<origin xyz="-0.019641820000000004276 -1.3877787807814456755e-17 -0.036182300000000000573" rpy="1.570796326794896558 1.0769274009316926161e-14 8.2714011591809387361e-29" />
<parent link="t_2-3_bracket_3" />
<child link="t_2-6_pin_2" />
<axis xyz="0 0 1"/>
<limit effort="1" velocity="20" />
<joint_properties friction="0.0"/>
</joint>

<joint name="caster_shaft3" type="fixed">
<origin xyz="-0.020675599999999932921 -0.010337799999999983808 -0.0025844500000000228401" rpy="0 2.7644905162743880414e-17 -2.7755575615620445582e-17" />
<parent link="t_2-2_mouting_plate_2" />
<child link="t_2-3_bracket_3" />
<axis xyz="0 0 1"/>
<limit effort="1" velocity="20" />
<joint_properties friction="0.0"/>
</joint>

<link name="t_2-3_bracket_4">
<visual>
<origin xyz="-0.045486319999999996755 0 0" rpy="1.570796326794896558 1.1067045288622257528e-19 8.4757502241068892055e-30" />
<geometry>
<mesh filename="package://nashbot/description/t_2-3_bracket.stl"/>
</geometry>
<material name="t_2-3_bracket_material">
<color rgba="0.79607843137254896693 0.82352941176470584317 0.9372549019607843146 1.0"/>
</material>
</visual>
<collision>
<origin xyz="-0.045486319999999996755 0 0" rpy="1.570796326794896558 1.1067045288622257528e-19 8.4757502241068892055e-30" />
<geometry>
<mesh filename="package://nashbot/description/t_2-3_bracket.stl"/>
</geometry>
</collision>
<inertial>
<origin xyz="8.3566322151090721704e-05 -5.7832354076137497629e-20 -0.020996006880772091763" rpy="0 0 0"/>
<mass value="0.030960253599026488214" />
<inertia ixx="4.5924729635141921347e-06" ixy="1.1650242566680388526e-34"  ixz="-2.4512710256687422179e-06" iyy="9.4662576262463118092e-06" iyz="-3.5711482065350515578e-35" izz="4.9083136439462329159e-06" />
</inertial>
</link>

<joint name="caster_shaft4" type="fixed">
<origin xyz="-0.020675599999999988432 0.010337800000000015033 -0.0025844500000000159012" rpy="0 2.7644905162743880414e-17 -2.7755575615620445582e-17" />
<parent link="t_2-2_mouting_plate_2" />
<child link="t_2-3_bracket_4" />
<axis xyz="0 0 1"/>
<limit effort="1" velocity="20" />
<joint_properties friction="0.0"/>
</joint>

<joint name="caster_base_mount2" type="continuous">
<origin xyz="-1.2143064331837649661e-17 0 -0.04000000000000001471" rpy="-6.9365135332916969927e-15 1.1217224233694430174e-15 -1.4123025265630571035" />
<parent link="link_base" />
<child link="t_2-2_mouting_plate_2" />
<axis xyz="0 0 1"/>
<limit effort="1" velocity="20" />
<joint_properties friction="0.0"/>
</joint>

<joint name="arm_base_fixed" type="fixed">
<origin xyz="0.035003417238566141012 -0.080546758170579296765 -0.009999999999999995004" rpy="3.3280069439011304169e-31 -3.2355623065705633491e-32 -5.0074178554068269025e-33" />
<parent link="link_arm_mount_base" />
<child link="link_base" />
<axis xyz="0 0 1"/>
<limit effort="1" velocity="20" />
<joint_properties friction="0.0"/>
</joint>

<joint name="slider_bearing" type="fixed">
<origin xyz="-0.028031642234836617877 -0.13539226875249418813 0.082270123761849736632" rpy="8.3266726846886284472e-17 -1.3877787807814456755e-17 -1.3877787807814481407e-17" />
<parent link="link_lead_screw" />
<child link="link_arm_mount_base" />
<axis xyz="0 0 1"/>
<limit effort="1" velocity="20" />
<joint_properties friction="0.0"/>
</joint>


</robot>
